Workbook
Name UOM: 'revised format'!$H$1

Sheet revised format
A1: Product ID | B1: Design ID( Fabric Code HL GENERATED) | C1: Cost Item category | D1: Cost Item | E1: Fabric Quality Description -Count/Construction/ GSM OR GLM/Content/Finishes/Fabric name and type /CW/GAUGE | F1: Item Type | G1: Quantity | H1: qty UOM | I1: HS Code | J1: Duty% | K1: Price without GST | L1: Base Total(W/o GST Factor) | M1: Base Total(With GST) | N1: GST | O1: Input Cost(on Base cost w/o GST factor) | P1: Currency | Q1: Fabric Type | R1: Fabric Finish | S1: Fabric Construction | T1: Knit Gauge | U1: Cuttable Width | V1: Source | W1: Costing Scenario | X1: Action
A2: YAS26ZWEWYF72145 | C2: Fabric | D2: Main Fabric | E2: 90% Cotton, 10% Linen | F2: F | L2: =G2*K2 -> 0 | M2: =L2+O2 -> 0 | N2: 0.05 | O2: =L2*N2 -> 0 | P2: INR | V2: VENDOR | X2: C
A3: BRAND - YOUSTA
A4: Vendor Name | C4: Fabric | D4: Trim Fabric1 | F4: F | L4: =G4*K4 -> 0 | M4: =L4+O4 -> 0 | N4: 0.05 | O4: =L4*N4 -> 0 | P4: INR | V4: VENDOR | X4: C
A5: UNITED TEXTILE MILL PVT LTD | C5: Fabric | D5: Trim Fabric2 | L5: =G5*K5 -> 0 | M5: =L5+O5 -> 0 | O5: =L5*N5 -> 0 | P5: INR | X5: C
A6: Vendor Code | C6: Fabric | D6: Trim Fabric3 | L6: =G6*K6 -> 0 | M6: =L6+O6 -> 0 | O6: =L6*N6 -> 0 | P6: INR
A7: Vendor Code - 32026735 | C7: Fabric | L7: =G7*K7 -> 0 | M7: =L7+O7 -> 0 | O7: =L7*N7 -> 0 | P7: INR
C8: Fabric | L8: =G8*K8 -> 0 | M8: =L8+O8 -> 0 | O8: =L8*N8 -> 0 | P8: INR
A9: L- | C9: Fabric | L9: =G9*K9 -> 0 | M9: =L9+O9 -> 0 | O9: =L9*N9 -> 0 | P9: INR
A10: B0- | C10: Fabric | L10: =G10*K10 -> 0 | M10: =L10+O10 -> 0 | O10: =L10*N10 -> 0 | P10: INR
C11: Fabric | L11: =G11*K11 -> 0 | M11: =L11+O11 -> 0 | O11: =L11*N11 -> 0 | P11: INR
C12: Fabric | L12: =G12*K12 -> 0 | M12: =L12+O12 -> 0 | O12: =L12*N12 -> 0 | P12: INR
C13: Sewing trims | D13: Sewing Thread | F13: Cost | G13: 1 | K13: 3.5 | L13: =G13*K13 -> 3.5 | M13: =L13+O13 -> 3.92 | N13: 0.12 | O13: =L13*N13 -> 0.42 | P13: INR | X13: C
C14: Sewing trims | D14: Fusing | G14: 0 | H14: Piece | L14: =G14*K14 -> 0 | M14: =L14+O14 -> 0 | O14: =L14*N14 -> 0 | P14: INR | X14: C
C15: Sewing trims | D15: MOP Buttons | G15: 0 | H15: Piece | L15: =G15*K15 -> 0 | M15: =L15+O15 -> 0 | O15: =L15*N15 -> 0 | P15: INR
C16: Sewing trims | D16: Buttons | G16: 0 | H16: Piece | L16: =G16*K16 -> 0 | M16: =L16+O16 -> 0 | O16: =L16*N16 -> 0 | P16: INR
C17: Sewing trims | D17: Shank/Snap | G17: 0 | H17: Piece | L17: =G17*K17 -> 0 | M17: =L17+O17 -> 0 | O17: =L17*N17 -> 0 | P17: INR
C18: Sewing trims | D18: Rivets | G18: 0 | H18: Piece | L18: =G18*K18 -> 0 | M18: =L18+O18 -> 0 | O18: =L18*N18 -> 0 | P18: INR
C19: Sewing trims | D19: Eyelet | G19: 0 | H19: Piece | L19: =G19*K19 -> 0 | M19: =L19+O19 -> 0 | O19: =L19*N19 -> 0 | P19: INR
C20: Sewing trims | D20: LACE | G20: 0 | H20: Piece | L20: =G20*K20 -> 0 | M20: =L20+O20 -> 0 | O20: =L20*N20 -> 0 | P20: INR
C21: Sewing trims | D21: Elastic | E21: 1.5 cm | G21: 0 | L21: =G21*K21 -> 0 | M21: =L21+O21 -> 0 | O21: =L21*N21 -> 0 | P21: INR
C22: Sewing trims | D22: Adjustable elastic | G22: 0 | H22: Piece | L22: =G22*K22 -> 0 | M22: =L22+O22 -> 0 | O22: =L22*N22 -> 0 | P22: INR
C23: Sewing trims | D23: Zipper | E23: DTM zipper | G23: 1 | H23: Piece | L23: =G23*K23 -> 0 | M23: =L23+O23 -> 0 | O23: =L23*N23 -> 0 | P23: INR
C24: Sewing trims | D24: Others | G24: 0 | H24: Piece | L24: =G24*K24 -> 0 | M24: =L24+O24 -> 0 | O24: =L24*N24 -> 0 | P24: INR
C25: Sewing trims | D25: Others | G25: 0 | H25: Piece | L25: =G25*K25 -> 0 | M25: =L25+O25 -> 0 | O25: =L25*N25 -> 0 | P25: INR
C26: Sewing trims | D26: Others | G26: 0 | H26: Piece | L26: =G26*K26 -> 0 | M26: =L26+O26 -> 0 | O26: =L26*N26 -> 0 | P26: INR
C27: Sewing trims | L27: =G27*K27 -> 0 | M27: =L27+O27 -> 0 | O27: =L27*N27 -> 0 | P27: INR
C28: Sewing trims | L28: =G28*K28 -> 0 | M28: =L28+O28 -> 0 | O28: =L28*N28 -> 0 | P28: INR
C29: Sewing trims | L29: =G29*K29 -> 0 | M29: =L29+O29 -> 0 | O29: =L29*N29 -> 0 | P29: INR
C30: Sewing trims | L30: =G30*K30 -> 0 | M30: =L30+O30 -> 0 | O30: =L30*N30 -> 0 | P30: INR
C31: Label & Tags | D31: Main Label | F31: L | G31: 1 | H31: Piece | K31: 1.2 | L31: =G31*K31 -> 1.2 | M31: =L31+O31 -> 1.344 | N31: 0.12 | O31: =L31*N31 -> 0.144 | P31: INR | X31: C
C32: Label & Tags | D32: Size Label | F32: L | G32: 0 | H32: Piece | K32: 0 | L32: =G32*K32 -> 0 | M32: =L32+O32 -> 0 | N32: 0.12 | O32: =L32*N32 -> 0 | P32: INR | X32: C
C33: Label & Tags | D33: Wase Care | F33: L | G33: 1 | H33: Piece | K33: 0.5 | L33: =G33*K33 -> 0.5 | M33: =L33+O33 -> 0.56 | N33: 0.12 | O33: =L33*N33 -> 0.06 | P33: INR | X33: C
C34: Label & Tags | D34: Main tag | F34: Cost | G34: 1 | H34: Piece | K34: 3.1 | L34: =G34*K34 -> 3.1 | M34: =L34+O34 -> 3.658 | N34: 0.18 | O34: =L34*N34 -> 0.558 | P34: INR | X34: C
C35: Label & Tags | D35: Disclaimer Tag | F35: Cost | G35: 1 | H35: Piece | L35: =G35*K35 -> 0 | M35: =L35+O35 -> 0 | N35: 0.12 | O35: =L35*N35 -> 0 | P35: INR | X35: C
C36: Label & Tags | D36: Barcode | F36: Cost | G36: 1 | H36: Piece | L36: =G36*K36 -> 0 | M36: =L36+O36 -> 0 | O36: =L36*N36 -> 0 | P36: INR | X36: C
C37: Label & Tags | D37: Transparent Tag | F37: Cost | G37: 1 | H37: Piece | L37: =G37*K37 -> 0 | M37: =L37+O37 -> 0 | O37: =L37*N37 -> 0 | P37: INR | X37: C
C38: Label & Tags | L38: =G38*K38 -> 0 | M38: =L38+O38 -> 0 | O38: =L38*N38 -> 0 | P38: INR
C39: Label & Tags | L39: =G39*K39 -> 0 | M39: =L39+O39 -> 0 | O39: =L39*N39 -> 0 | P39: INR
C40: Label & Tags | L40: =G40*K40 -> 0 | M40: =L40+O40 -> 0 | O40: =L40*N40 -> 0 | P40: INR
...

Sheet excel update 
A3: sl no | B3: Brand Name | C3: Style No | D3: Total Qty | E3: NON MSME CS price | F3: MSME CS PRICE | G3: Margin% | H3: Rejection% | I3: CM | J3: Fabric Quality Description -Count/Construction/ GSM OR GLM/Content/Finishes/Fabric name and type /CW/GAUGE | K3: Main Fabric Price | L3: Main Fabric Qty- yy | M3: Trim Fabric 1 | N3: Trim Fabric 1 Price | O3: Trim Fabric 1 Qty- yy | P3: Trim Fabric 2 | Q3: Trim Fabric 2 Price | R3: Trim Fabric 2 Qty- yy | S3: Trim Fabric 3 | T3: Trim Fabric 3 Price | U3: Trim Fabric 3 Qty- yy | V3: MSME | W3: PM Name | X3: Vendor | Y3: Vendor Code | Z3: Date of CS rcvd | AA3: Validation remarks | AB3: Validation Date
A4: 1 | B4: YOUSTA | C4: ='revised format'!A2 -> YAS26ZWEWYF72145 | E4: ='revised format'!L69 -> 103.5756 | F4: ='revised format'!L71 -> 0 | G4: ='revised format'!K66 -> 0.12 | H4: ='revised format'!K65 -> 0.02 | I4: ='revised format'!K62 -> 75 | J4: ='revised format'!E2 -> 90% Cotton, 10% Linen | K4: ='revised format'!K2 -> 0 | L4: ='revised format'!G2 -> 0 | M4: ='revised format'!E4 -> 0 | N4: ='revised format'!K4 -> 0 | O4: ='revised format'!G4 -> 0 | P4: ='revised format'!E5 -> 0 | Q4: ='revised format'!K5 -> 0 | R4: ='revised format'!G5 -> 0 | S4: ='revised format'!K6 -> 0 | T4: ='revised format'!K6 -> 0 | U4: ='revised format'!G6 -> 0 | V4: ='revised format'!L70 -> 0 | X4: ='revised format'!A5 -> UNITED TEXTILE MILL PVT LTD | Y4: ='revised format'!A7 -> Vendor Code - 32026735
